Traceback (most recent call last):
  File "/infai/heuser0000/stp-pho-solver/experiments/data/exp1/runs-00001-00100/00001/run", line 21, in <module>
    Call(['../../cmake-build-debug', '-s 1 2 6 3 5 10 0 7 4 8 9 11 12 13 14 15 -p 0 1 2 3 4 5 -p 0 6 7 8 9 10 -p 0 11 12 13 14 15'], hard_stderr_limit=10240, hard_stdout_limit=10240, memory_limit=2048, name='solve', soft_stderr_limit=64, soft_stdout_limit=1024, time_limit=1800, **redirects).wait()
  File "/infai/heuser0000/stp-pho-solver/experiments/.venv/lib/python3.10/site-packages/lab/calls/call.py", line 95, in __init__
    self.process = subprocess.Popen(args, preexec_fn=prepare_call, **kwargs)
  File "/scicore/soft/apps/Python/3.10.4-GCCcore-11.3.0/lib/python3.10/subprocess.py", line 966, in __init__
    self._execute_child(args, executable, preexec_fn, close_fds,
  File "/scicore/soft/apps/Python/3.10.4-GCCcore-11.3.0/lib/python3.10/subprocess.py", line 1842, in _execute_child
    raise child_exception_type(errno_num, err_msg, err_filename)
PermissionError: [Errno 13] Permission denied: '../../cmake-build-debug'
The run script finished with exit code 1
